// these should normally be in your jest setupTestFrameworkScriptFile
import 'react-testing-library/cleanup-after-each'
import 'jest-dom/extend-expect'

import {render, fireEvent} from 'react-testing-library'
import {reportError as mockReportError} from '../api'
import {ErrorBoundary} from '../error-boundary'

jest.mock('../api', () => {
  return {
    reportError: jest.fn(() => Promise.resolve({success: true})),
  }
})

beforeEach(() => {
  // when the error's thrown a bunch of console.errors are called even though
  // the error boundary handles the error. This makes the test output noisy,
  // so we'll mock out console.error
  jest.spyOn(console, 'error').mockImplementation(() => {})
})

afterEach(() => {
  console.error.mockRestore()
})

function Bomb({shouldThrow}) {
  if (shouldThrow) {
    throw new Error('ðŸ’£')
  } else {
    return null
  }
}

test('calls reportError and renders that there was a problem', () => {
  const {container, rerender, getByText} = render(
    <ErrorBoundary>
      <Bomb />
    </ErrorBoundary>,
  )

  rerender(
    <ErrorBoundary>
      <Bomb shouldThrow={true} />
    </ErrorBoundary>,
  )

  expect(mockReportError).toHaveBeenCalledTimes(1)
  const error = expect.any(Error)
  const info = {componentStack: expect.stringContaining('Bomb')}
  expect(mockReportError).toHaveBeenCalledWith(error, info)

  expect(container).toHaveTextContent('There was a problem')

  // by mocking out console.error we may inadvertantly be missing out on logs
  // in the future that could be important, so let's reduce that liklihood by
  // adding an assertion for how frequently console.error is called.
  expect(console.error).toHaveBeenCalledTimes(2)

  // ensure the user can recover from errors
  console.error.mockClear()
  mockReportError.mockClear()

  rerender(
    <ErrorBoundary>
      <Bomb />
    </ErrorBoundary>,
  )
  fireEvent.click(getByText(/try again/i))

  expect(mockReportError).not.toHaveBeenCalled()
  expect(console.error).not.toHaveBeenCalled()
  expect(container).not.toHaveTextContent('There was a problem')
})
